<robot name="vision_bot">

  <!--
    - take a look into inertia_calculations.txt file
    Inertia Values https://github.com/RobotnikAutomation/rb1_base_common/issues/1
-   Get the inertia tensor
-   Scale
-   Divide by the volume
-   Divide by scale*2 (scale -sqaurred)
-   multiply with  mass you wantto give
Thats why we use xacros
<uri>model://maze_bot/meshes/base_link.stl</uri>
 -->

  <link name="base_footprint" />
<!-- ////////////////////////////////////  BASE LINK //////////////////////////////////////////////// -->
  <link name="base_link">
    <inertial>
      <mass value="4" />
      <origin xyz="0 0 0.1" rpy="0 0 0" />
      <inertia ixx="0.00355" iyy="0.01265" izz="0.013832" ixy="0.0" ixz="0.0" iyz="0.0" />
    </inertial>

    <visual>
      <geometry>
        <mesh filename="package://vision_bot/meshes/base.dae" />

      </geometry>

    </visual>

    <collision>
      <geometry>
        <mesh filename="package://vision_bot/meshes/base.dae" />
      </geometry>
    </collision>

  </link>
  <joint name="base_joint" type="fixed">
    <parent link="base_footprint" />
    <child link="base_link" />
    <origin rpy="0 0 0" xyz="0 0 0.14" />
  </joint>
<!-- ////////////////////////////////////  COVER LINK //////////////////////////////////////////////// -->

  <link name="cover_link">
    <inertial>
      <mass value="0.5" />
      <origin xyz="0 0 0.1" rpy="0 0 0" />
      <inertia ixx="0.00355" iyy="0.01265" izz="0.013832" ixy="0.0" ixz="0.0" iyz="0.0" />
    </inertial>

    <visual>
      <geometry>
        <mesh filename="package://vision_bot/meshes/cover.dae" />
      </geometry>

    </visual>

    <collision>
      <geometry>
        <mesh filename="package://vision_bot/meshes/cover.dae" />
      </geometry>
    </collision>


  </link>

  <joint name="cover_joint" type="fixed">
    <parent link="base_link" />
    <child link="cover_link" />
    <origin xyz="0.0015  0 0.08" rpy="0 0 0" />

  </joint>

<!-- ////////////////////////////////////  Right Wheel LINK //////////////////////////////////////////////// -->

  <link name="wheel_right_link">
    <inertial>
      <mass value="1" />
      <inertia ixx="0.001444223" iyy="0.00280875" izz="0.001444223" ixy="0.0" ixz="0.0" iyz="0.0" />
      <origin />
    </inertial>

    <visual>
      <origin xyz="0.0 0.0 0.0" rpy="0.0 0.0 3.14"/>
      <geometry>
        <mesh filename="package://vision_bot/meshes/wheel.dae" />
      </geometry>


    </visual>

    <collision>
      <geometry>
        <mesh filename="package://vision_bot/meshes/wheel.dae" />
      </geometry>
    </collision>

  </link>

  <joint name="wheel_right_joint" type="continuous">
    <origin xyz="-0.232  0.14 -0.045  " rpy="0 0.0 -1.57" />
    <parent link="base_link" />
    <child link="wheel_right_link" />
    <axis xyz="0 1 0" />
  </joint>
<!-- ////////////////////////////////////  Left Wheel LINK //////////////////////////////////////////////// -->

  <link name="wheel_left_link">
    <inertial>
      <mass value="1" />
      <inertia ixx="0.001444223" iyy="0.00280875" izz="0.001444223" ixy="0.0" ixz="0.0" iyz="0.0" />
      <origin />
    </inertial>

    <visual>

      <geometry>
        <mesh filename="package://vision_bot/meshes/wheel.dae" />
      </geometry>


    </visual>

    <collision>
      <geometry>
        <mesh filename="package://vision_bot/meshes/wheel.dae" />
      </geometry>
    </collision>
  </link>

  <joint name="wheel_left_joint" type="continuous">
    <origin xyz="0.233  0.14 -0.045  " rpy="0 0.0 -1.57" />
    <parent link="base_link" />
    <child link="wheel_left_link" />
    <axis xyz="0.0 1 0" />

  </joint>
<!-- ////////////////////////////////////  Caster of Wheel LINK //////////////////////////////////////////////// -->
<!--
<link name="front_caster_of_wheel">
  <visual>
      <geometry>
          <box size="0.1 0.1 0.1"/>
      </geometry>
      <material name="green">
          <color rgba="0.0 0.1 0.0 1"/>
      </material>
  </visual>
  <collision>
      <geometry>
          <box size="0.1 0.1 0.1"/>
      </geometry>
  </collision>
  <inertial>
      <mass value="0.1"/>
      <inertia ixx="0.00083" ixy="0" ixz="0" iyy="0.00083" iyz="0.0" izz="0.000167"/>
  </inertial>
</link>
<joint name="front_caster_of_wheel_joint" type="continuous">
 <axis xyz="0.0 0.0 1"/>
 <parent link="base_link"/>
 <child link="front_caster_of_wheel"/>
 <origin xyz="0 -0.19 -0.07" rpy="0.0 0.0 -1.57"/>
</joint> -->
<link name="caster_holder_link">

  <inertial>
    <mass value="0.1" />
    <inertia ixx="0.0001295" iyy="0.0001295" izz="0.000199322" ixy="0.0" ixz="0.0" iyz="0.0" />
    <origin />
  </inertial>

  <visual>
    <geometry>
      <mesh filename="package://vision_bot/meshes/caster_holder.dae" />
    </geometry>
  </visual>

  <collision>
    <geometry>
      <mesh filename="package://vision_bot/meshes/caster_holder.dae" />
    </geometry>
  </collision>

</link>

<joint name="caster_holder_joint" type="continuous">
  <origin xyz="0 -0.19 -0.015" rpy="0.0 0.0 0.0" />
  <axis xyz="0 0 1" />
  <parent link="base_link" />
  <child link="caster_holder_link" />
</joint>

<!-- ////////////////////////////////////  Front Wheel LINK //////////////////////////////////////////////// -->

<!-- <link name="front_wheel">
  <visual>
      <geometry>
          <cylinder radius="0.035" length="0.05"/>
      </geometry>
      <material name="black">

      </material>

  </visual>
  <collision>
      <geometry>
          <cylinder radius="0.035" length="0.05"/>
      </geometry>
  </collision>
  <inertial>
      <mass value="0.1"/>
      <inertia ixx="5.1458e-5" ixy="0" ixz="0" iyy="5.1458e-5" iyz="0.0" izz="6.125e-5"/>
  </inertial>
</link>

<joint name="front_wheel_joint" type="continuous">
  <axis xyz="0.0 0.0 1"/>
  <parent link="front_caster_of_wheel"/>
  <child link="front_wheel"/>
  <origin xyz="0.05 0.0 -0.05" rpy="-1.5708 0.0 0.0"/>

</joint> -->


  <link name="caster_wheel_link">
    <inertial>
      <mass value="0.1" />
      <inertia ixx="0.0001295" iyy="0.0001295" izz="0.000199322" ixy="0.0" ixz="0.0" iyz="0.0" />
      <origin />
    </inertial>
    <visual>
      <geometry>
        <mesh filename="package://vision_bot/meshes/caster_wheel.dae" />
      </geometry>
    </visual>
    <collision>
      <geometry>
        <mesh filename="package://vision_bot/meshes/caster_wheel.dae" />
      </geometry>
    </collision>
  </link>

  <joint name="caster_wheel_joint" type="continuous">
    <origin xyz="0 -0.003  -0.086" rpy="0.0 0.0 0.0" />
    <axis xyz="1 0 0" />
    <parent link="caster_holder_link" />
    <child link="caster_wheel_link" />
  </joint>


<!-- ////////////////////////////////////  Camera LINK //////////////////////////////////////////////// -->

  <link name="camera_link">

    <inertial>
      <mass value="0.75" />
      <inertia ixx="0.0001295" iyy="0.0001295" izz="0.000199322" ixy="0.0" ixz="0.0" iyz="0.0" />
      <origin />
    </inertial>

    <visual>
      <origin xyz="0.0 0.0 0.0" rpy="0.0 0.0 1.57"/>
      <geometry>
        <mesh filename="package://vision_bot/meshes/rpi_camera.dae" />
      </geometry>
    </visual>

    <collision>
      <geometry>
        <mesh filename="package://vision_bot/meshes/rpi_camera.dae" />
      </geometry>
    </collision>
  </link>

  <joint name="camera_joint" type="fixed">
    <origin xyz="0 -0.18 0.2" rpy="0.0 0 -1.57" />
    <parent link="base_link" />
    <child link="camera_link" />

  </joint>


    <gazebo reference="camera_link">
        <sensor type="camera" name="frontCam">
          <always_on>1</always_on>
          <visualize>1</visualize>
          <update_rate>30.0</update_rate>
          <camera name="head">
            <horizontal_fov>1.3962634</horizontal_fov>
            <image>
              <width>640</width>
              <height>480</height>
              <format>R8G8B8</format>
            </image>
            <clip>
              <near>0.02</near>
              <far>300</far>
            </clip>
            <noise>
              <type>gaussian</type>
              <mean>0.0</mean>
              <stddev>0.007</stddev>
            </noise>
          </camera>

          <plugin name="Vision_bot_camera" filename="libgazebo_ros_camera.so">
            <alwaysOn>true</alwaysOn>
            <updateRate>0.0</updateRate>
            <cameraName>/camera</cameraName>
            <imageTopicName>image_raw</imageTopicName>
            <cameraInfoTopicName>camera_info</cameraInfoTopicName>
            <frameName>camera_link</frameName>
            <hackBaseline>0.07</hackBaseline>
          </plugin>
        </sensor>
      </gazebo>




    <gazebo>
      <plugin filename="libgazebo_ros_diff_drive.so" name="vision_bot_controller">
        <odometry_frame>odom</odometry_frame>
        <commandTopic>cmd_vel</commandTopic>
        <publish_odom>true</publish_odom>
        <publish_odom_tf>true</publish_odom_tf>
        <update_rate>15.0</update_rate>
        <left_joint>wheel_left_joint</left_joint>
        <right_joint>wheel_right_joint</right_joint>
        <wheel_separation>0.4</wheel_separation>
        <wheel_diameter>0.2</wheel_diameter>
        <max_wheel_acceleration>2</max_wheel_acceleration>
        <robotBaseFrame>base_link</robotBaseFrame>

      </plugin>
    </gazebo>



</robot>